Workbook

Sheet Leyenda
A1: CapitalDex — Universo de empresas
A2: Generado el 2026-10-15 desde Yahoo Finance (yfinance). Datos con retraso; solo para diseño del juego.
A4: Celdas editables (texto azul, fondo amarillo):
A5: Empresas!Incluir — SI/NO. NO saca la empresa del juego.
A6: Empresas!Rareza manual — fuerza una rareza (Legendaria, Épica, Rara, Poco común, Común). Vacío = automática.
A7: Umbrales!B2:B6 — capitalización mínima (M USD) de cada rareza.
A8: Umbrales!C2:C6 — probabilidad de cada rareza en el gacha (deben sumar 100 %).
A9: Umbrales!B9:B10 — coeficiente y exponente de la fórmula de ingresos.
A10: FX!B — tipo de cambio a USD.
A12: Después de editar, ejecuta: npm run data (o python scripts/build_data.py) para regenerar el JSON del juego.
A13: Los umbrales y la fórmula de ingresos también están en src/game/balance.ts; mantenlos iguales.
A14: Nota: la moneda GBp (peniques) se normaliza a GBP porque Yahoo da la capitalización ya en libras.

Sheet Empresas
A1: Ticker | B1: Nombre | C1: País | D1: Código país | E1: Sector | F1: Industria | G1: Bolsa | H1: Moneda | I1: Cap. local (M) | J1: Tipo cambio a USD | K1: Cap. USD (M) | L1: Rareza | M1: Ingresos local (M) | N1: Beneficio local (M) | O1: Ingresos USD (M) | P1: Beneficio USD (M) | Q1: Rent. dividendo | R1: PER | S1: Índices | T1: Incluir | U1: Rareza manual | V1: Ingresos/s en juego
A2: NVDA | B2: NVIDIA Corporation | C2: United States | D2: US | E2: Tecnología | F2: Semiconductors | G2: NMS | H2: USD | I2: 5343731 | J2: =INDEX(FX!$B:$B,MATCH(H2,FX!$A:$A,0)) | K2: =I2*J2 | L2: =IF(U2<>"",U2,IF(K2>=Umbrales!$B$2,"Legendaria",IF(K2>=Umbrales!$B$3,"Épica",IF(K2>=Umbrales!$B$4,"Rara",IF(K2>=Umbrales!$B$5,"Poco común","Común"))))) | M2: 302970.01 | N2: 192880 | O2: =IF(M2="","",M2*J2) | P2: =IF(N2="","",N2*J2) | Q2: 0.0044 | R2: 28.89034 | S2: DOW30, NASDAQ100 | T2: SI | V2: =Umbrales!$B$9*(K2/1000)^Umbrales!$B$10
A3: AAPL | B3: Apple Inc. | C3: United States | D3: US | E3: Tecnología | F3: Consumer Electronics | G3: NMS | H3: USD | I3: 5005219.7 | J3: =INDEX(FX!$B:$B,MATCH(H3,FX!$A:$A,0)) | K3: =I3*J3 | L3: =IF(U3<>"",U3,IF(K3>=Umbrales!$B$2,"Legendaria",IF(K3>=Umbrales!$B$3,"Épica",IF(K3>=Umbrales!$B$4,"Rara",IF(K3>=Umbrales!$B$5,"Poco común","Común"))))) | M3: 466822.99 | N3: 128930 | O3: =IF(M3="","",M3*J3) | P3: =IF(N3="","",N3*J3) | Q3: 0.0032 | R3: 39.150684 | S3: DOW30, NASDAQ100 | T3: SI | V3: =Umbrales!$B$9*(K3/1000)^Umbrales!$B$10
A4: GOOGL | B4: Alphabet Inc. | C4: United States | D4: US | E4: Comunicación | F4: Internet Content & Information | G4: NMS | H4: USD | I4: 4251614.7 | J4: =INDEX(FX!$B:$B,MATCH(H4,FX!$A:$A,0)) | K4: =I4*J4 | L4: =IF(U4<>"",U4,IF(K4>=Umbrales!$B$2,"Legendaria",IF(K4>=Umbrales!$B$3,"Épica",IF(K4>=Umbrales!$B$4,"Rara",IF(K4>=Umbrales!$B$5,"Poco común","Común"))))) | M4: 445865.98 | N4: 244118.99 | O4: =IF(M4="","",M4*J4) | P4: =IF(N4="","",N4*J4) | Q4: 0.0025 | R4: 17.754852 | S4: NASDAQ100 | T4: SI | V4: =Umbrales!$B$9*(K4/1000)^Umbrales!$B$10
A5: MSFT | B5: Microsoft Corporation | C5: United States | D5: US | E5: Tecnología | F5: Software - Infrastructure | G5: NMS | H5: USD | I5: 3962939.6 | J5: =INDEX(FX!$B:$B,MATCH(H5,FX!$A:$A,0)) | K5: =I5*J5 | L5: =IF(U5<>"",U5,IF(K5>=Umbrales!$B$2,"Legendaria",IF(K5>=Umbrales!$B$3,"Épica",IF(K5>=Umbrales!$B$4,"Rara",IF(K5>=Umbrales!$B$5,"Poco común","Común"))))) | M5: 331839.01 | N5: 133749 | O5: =IF(M5="","",M5*J5) | P5: =IF(N5="","",N5*J5) | Q5: 0.0072 | R5: 30.067043 | S5: DOW30, NASDAQ100 | T5: SI | V5: =Umbrales!$B$9*(K5/1000)^Umbrales!$B$10
A6: AMZN | B6: Amazon.com, Inc. | C6: United States | D6: US | E6: Consumo cíclico | F6: Internet Retail | G6: NMS | H6: USD | I6: 2740586.5 | J6: =INDEX(FX!$B:$B,MATCH(H6,FX!$A:$A,0)) | K6: =I6*J6 | L6: =IF(U6<>"",U6,IF(K6>=Umbrales!$B$2,"Legendaria",IF(K6>=Umbrales!$B$3,"Épica",IF(K6>=Umbrales!$B$4,"Rara",IF(K6>=Umbrales!$B$5,"Poco común","Común"))))) | M6: 775680.03 | N6: 135281 | O6: =IF(M6="","",M6*J6) | P6: =IF(N6="","",N6*J6) | Q6: 0 | R6: 20.440868 | S6: DOW30, NASDAQ100 | T6: SI | V6: =Umbrales!$B$9*(K6/1000)^Umbrales!$B$10
A7: TSM | B7: Taiwan Semiconductor Manufacturing Company Limited | C7: Taiwan | D7: TW | E7: Tecnología | F7: Semiconductors | G7: NYQ | H7: USD | I7: 2230183.8 | J7: =INDEX(FX!$B:$B,MATCH(H7,FX!$A:$A,0)) | K7: =I7*J7 | L7: =IF(U7<>"",U7,IF(K7>=Umbrales!$B$2,"Legendaria",IF(K7>=Umbrales!$B$3,"Épica",IF(K7>=Umbrales!$B$4,"Rara",IF(K7>=Umbrales!$B$5,"Poco común","Común"))))) | M7: 4440492.3 | N7: 2216808.4 | O7: =IF(M7="","",M7*J7) | P7: =IF(N7="","",N7*J7) | Q7: 0.0085 | R7: 32.355156 | S7: ASIA_TOP | T7: SI | V7: =Umbrales!$B$9*(K7/1000)^Umbrales!$B$10
A8: META | B8: Meta Platforms, Inc. | C8: United States | D8: US | E8: Comunicación | F8: Internet Content & Information | G8: NMS | H8: USD | I8: 1878887.6 | J8: =INDEX(FX!$B:$B,MATCH(H8,FX!$A:$A,0)) | K8: =I8*J8 | L8: =IF(U8<>"",U8,IF(K8>=Umbrales!$B$2,"Legendaria",IF(K8>=Umbrales!$B$3,"Épica",IF(K8>=Umbrales!$B$4,"Rara",IF(K8>=Umbrales!$B$5,"Poco común","Común"))))) | M8: 228246.99 | N8: 68097.999 | O8: =IF(M8="","",M8*J8) | P8: =IF(N8="","",N8*J8) | Q8: 0.0028 | R8: 27.78975 | S8: NASDAQ100 | T8: SI | V8: =Umbrales!$B$9*(K8/1000)^Umbrales!$B$10
A9: AVGO | B9: Broadcom Inc. | C9: United States | D9: US | E9: Tecnología | F9: Semiconductors | G9: NMS | H9: USD | I9: 1652869.4 | J9: =INDEX(FX!$B:$B,MATCH(H9,FX!$A:$A,0)) | K9: =I9*J9 | L9: =IF(U9<>"",U9,IF(K9>=Umbrales!$B$2,"Legendaria",IF(K9>=Umbrales!$B$3,"Épica",IF(K9>=Umbrales!$B$4,"Rara",IF(K9>=Umbrales!$B$5,"Poco común","Común"))))) | M9: 89103.999 | N9: 38265 | O9: =IF(M9="","",M9*J9) | P9: =IF(N9="","",N9*J9) | Q9: 0.0073 | R9: 45.619236 | S9: NASDAQ100 | T9: SI | V9: =Umbrales!$B$9*(K9/1000)^Umbrales!$B$10
A10: 2222.SR | B10: Saudi Arabian Oil Company | C10: Saudi Arabia | D10: SA | E10: Energía | F10: Oil & Gas Integrated | G10: SAU | H10: SAR | I10: 6110580.8 | J10: =INDEX(FX!$B:$B,MATCH(H10,FX!$A:$A,0)) | K10: =I10*J10 | L10: =IF(U10<>"",U10,IF(K10>=Umbrales!$B$2,"Legendaria",IF(K10>=Umbrales!$B$3,"Épica",IF(K10>=Umbrales!$B$4,"Rara",IF(K10>=Umbrales!$B$5,"Poco común","Común"))))) | M10: 1823483 | N10: 408371 | O10: =IF(M10="","",M10*J10) | P10: =IF(N10="","",N10*J10) | Q10: 0.0535 | R10: 14.686047 | S10: ASIA_TOP | T10: SI | V10: =Umbrales!$B$9*(K10/1000)^Umbrales!$B$10
A11: TSLA | B11: Tesla, Inc. | C11: United States | D11: US | E11: Consumo cíclico | F11: Auto Manufacturers | G11: NMS | H11: USD | I11: 1450115.9 | J11: =INDEX(FX!$B:$B,MATCH(H11,FX!$A:$A,0)) | K11: =I11*J11 | L11: =IF(U11<>"",U11,IF(K11>=Umbrales!$B$2,"Legendaria",IF(K11>=Umbrales!$B$3,"Épica",IF(K11>=Umbrales!$B$4,"Rara",IF(K11>=Umbrales!$B$5,"Poco común","Común"))))) | M11: 103619 | N11: 3806.0001 | O11: =IF(M11="","",M11*J11) | P11: =IF(N11="","",N11*J11) | Q11: 0 | R11: 339.96295 | S11: NASDAQ100 | T11: SI | V11: =Umbrales!$B$9*(K11/1000)^Umbrales!$B$10
A12: BRK-B | B12: Berkshire Hathaway Inc. | C12: United States | D12: US | E12: Finanzas | F12: Insurance - Diversified | G12: NYQ | H12: USD | I12: 1126762.5 | J12: =INDEX(FX!$B:$B,MATCH(H12,FX!$A:$A,0)) | K12: =I12*J12 | L12: =IF(U12<>"",U12,IF(K12>=Umbrales!$B$2,"Legendaria",IF(K12>=Umbrales!$B$3,"Épica",IF(K12>=Umbrales!$B$4,"Rara",IF(K12>=Umbrales!$B$5,"Poco común","Común"))))) | M12: 384687.01 | N12: 85768.004 | O12: =IF(M12="","",M12*J12) | P12: =IF(N12="","",N12*J12) | Q12: 0 | R12: 13.093283 | T12: SI | V12: =Umbrales!$B$9*(K12/1000)^Umbrales!$B$10
A13: LLY | B13: Eli Lilly and Company | C13: United States | D13: US | E13: Salud | F13: Drug Manufacturers - General | G13: NYQ | H13: USD | I13: 1077418.9 | J13: =INDEX(FX!$B:$B,MATCH(H13,FX!$A:$A,0)) | K13: =I13*J13 | L13: =IF(U13<>"",U13,IF(K13>=Umbrales!$B$2,"Legendaria",IF(K13>=Umbrales!$B$3,"Épica",IF(K13>=Umbrales!$B$4,"Rara",IF(K13>=Umbrales!$B$5,"Poco común","Común"))))) | M13: 79666.004 | N13: 26710.999 | O13: =IF(M13="","",M13*J13) | P13: =IF(N13="","",N13*J13) | Q13: 0.0059 | R13: 39.155815 | T13: SI | V13: =Umbrales!$B$9*(K13/1000)^Umbrales!$B$10
A14: MU | B14: Micron Technology, Inc. | C14: United States | D14: US | E14: Tecnología | F14: Semiconductors | G14: NMS | H14: USD | I14: 1034267.9 | J14: =INDEX(FX!$B:$B,MATCH(H14,FX!$A:$A,0)) | K14: =I14*J14 | L14: =IF(U14<>"",U14,IF(K14>=Umbrales!$B$2,"Legendaria",IF(K14>=Umbrales!$B$3,"Épica",IF(K14>=Umbrales!$B$4,"Rara",IF(K14>=Umbrales!$B$5,"Poco común","Común"))))) | M14: 133188 | N14: 84968.997 | O14: =IF(M14="","",M14*J14) | P14: =IF(N14="","",N14*J14) | Q14: 0.0006 | R14: 12.824495 | S14: NASDAQ100 | T14: SI | V14: =Umbrales!$B$9*(K14/1000)^Umbrales!$B$10
A15: 005930.KS | B15: Samsung Electronics Co., Ltd. | C15: South Korea | D15: KR | E15: Tecnología | F15: Consumer Electronics | G15: KSC | H15: KRW | I15: 1.3675038e+09 | J15: =INDEX(FX!$B:$B,MATCH(H15,FX!$A:$A,0)) | K15: =I15*J15 | L15: =IF(U15<>"",U15,IF(K15>=Umbrales!$B$2,"Legendaria",IF(K15>=Umbrales!$B$3,"Épica",IF(K15>=Umbrales!$B$4,"Rara",IF(K15>=Umbrales!$B$5,"Poco común","Común"))))) | M15: 4.8527205e+08 | N15: 1.3526468e+08 | O15: =IF(M15="","",M15*J15) | P15: =IF(N15="","",N15*J15) | Q15: 0.0064 | S15: ASIA_TOP | T15: SI | V15: =Umbrales!$B$9*(K15/1000)^Umbrales!$B$10
A16: AMD | B16: Advanced Micro Devices, Inc. | C16: United States | D16: US | E16: Tecnología | F16: Semiconductors | G16: NMS | H16: USD | I16: 931849.37 | J16: =INDEX(FX!$B:$B,MATCH(H16,FX!$A:$A,0)) | K16: =I16*J16 | L16: =IF(U16<>"",U16,IF(K16>=Umbrales!$B$2,"Legendaria",IF(K16>=Umbrales!$B$3,"Épica",IF(K16>=Umbrales!$B$4,"Rara",IF(K16>=Umbrales!$B$5,"Poco común","Común"))))) | M16: 41305.002 | N16: 6469.0002 | O16: =IF(M16="","",M16*J16) | P16: =IF(N16="","",N16*J16) | Q16: 0 | R16: 145.61734 | S16: NASDAQ100 | T16: SI | V16: =Umbrales!$B$9*(K16/1000)^Umbrales!$B$10
A17: WMT | B17: Walmart Inc. | C17: United States | D17: US | E17: Consumo básico | F17: Discount Stores | G17: NMS | H17: USD | I17: 921584.01 | J17: =INDEX(FX!$B:$B,MATCH(H17,FX!$A:$A,0)) | K17: =I17*J17 | L17: =IF(U17<>"",U17,IF(K17>=Umbrales!$B$2,"Legendaria",IF(K17>=Umbrales!$B$3,"Épica",IF(K17>=Umbrales!$B$4,"Rara",IF(K17>=Umbrales!$B$5,"Poco común","Común"))))) | M17: 735839.98 | N17: 22076 | O17: =IF(M17="","",M17*J17) | P17: =IF(N17="","",N17*J17) | Q17: 0.0088 | R17: 42.08696 | S17: DOW30 | T17: SI | V17: =Umbrales!$B$9*(K17/1000)^Umbrales!$B$10
A18: JPM | B18: JPMorgan Chase & Co. | C18: United States | D18: US | E18: Finanzas | F18: Banks - Diversified | G18: NYQ | H18: USD | I18: 890369.61 | J18: =INDEX(FX!$B:$B,MATCH(H18,FX!$A:$A,0)) | K18: =I18*J18 | L18: =IF(U18<>"",U18,IF(K18>=Umbrales!$B$2,"Legendaria",IF(K18>=Umbrales!$B$3,"Épica",IF(K18>=Umbrales!$B$4,"Rara",IF(K18>=Umbrales!$B$5,"Poco común","Común"))))) | M18: 190732.99 | N18: 64527 | O18: =IF(M18="","",M18*J18) | P18: =IF(N18="","",N18*J18) | Q18: 0.0199 | R18: 13.900497 | S18: DOW30 | T18: SI | V18: =Umbrales!$B$9*(K18/1000)^Umbrales!$B$10
A19: V | B19: Visa Inc. | C19: United States | D19: US | E19: Finanzas | F19: Credit Services | G19: NYQ | H19: USD | I19: 734853.14 | J19: =INDEX(FX!$B:$B,MATCH(H19,FX!$A:$A,0)) | K19: =I19*J19 | L19: =IF(U19<>"",U19,IF(K19>=Umbrales!$B$2,"Legendaria",IF(K19>=Umbrales!$B$3,"Épica",IF(K19>=Umbrales!$B$4,"Rara",IF(K19>=Umbrales!$B$5,"Poco común","Común"))))) | M19: 44487.999 | N19: 22397.999 | O19: =IF(M19="","",M19*J19) | P19: =IF(N19="","",N19*J19) | Q19: 0.0068 | R19: 33.31319 | S19: DOW30 | T19: SI | V19: =Umbrales!$B$9*(K19/1000)^Umbrales!$B$10
A20: XOM | B20: ExxonMobil Holdings Corporation | C20: United States | D20: US | E20: Energía | F20: Oil & Gas Integrated | G20: NYQ | H20: USD | I20: 727849.5 | J20: =INDEX(FX!$B:$B,MATCH(H20,FX!$A:$A,0)) | K20: =I20*J20 | L20: =IF(U20<>"",U20,IF(K20>=Umbrales!$B$2,"Legendaria",IF(K20>=Umbrales!$B$3,"Épica",IF(K20>=Umbrales!$B$4,"Rara",IF(K20>=Umbrales!$B$5,"Poco común","Común"))))) | M20: 361060.01 | N20: 32757 | O20: =IF(M20="","",M20*J20) | P20: =IF(N20="","",N20*J20) | Q20: 0.0237 | R20: 22.406328 | T20: SI | V20: =Umbrales!$B$9*(K20/1000)^Umbrales!$B$10
A21: 000660.KS | B21: SK hynix Inc. | C21: South Korea | D21: KR | E21: Tecnología | F21: Semiconductors | G21: KSC | H21: KRW | I21: 8.9737731e+08 | J21: =INDEX(FX!$B:$B,MATCH(H21,FX!$A:$A,0)) | K21: =I21*J21 | L21: =IF(U21<>"",U21,IF(K21>=Umbrales!$B$2,"Legendaria",IF(K21>=Umbrales!$B$3,"Épica",IF(K21>=Umbrales!$B$4,"Rara",IF(K21>=Umbrales!$B$5,"Poco común","Común"))))) | M21: 1.8917061e+08 | N21: 1.619654e+08 | O21: =IF(M21="","",M21*J21) | P21: =IF(N21="","",N21*J21) | Q21: 0.0011 | S21: ASIA_TOP | T21: SI | V21: =Umbrales!$B$9*(K21/1000)^Umbrales!$B$10
A22: ASML.AS | B22: ASML Holding N.V. | C22: Netherlands | D22: NL | E22: Tecnología | F22: Semiconductor Equipment & Materials | G22: AMS | H22: EUR | I22: 553027.17 | J22: =INDEX(FX!$B:$B,MATCH(H22,FX!$A:$A,0)) | K22: =I22*J22 | L22: =IF(U22<>"",U22,IF(K22>=Umbrales!$B$2,"Legendaria",IF(K22>=Umbrales!$B$3,"Épica",IF(K22>=Umbrales!$B$4,"Rara",IF(K22>=Umbrales!$B$5,"Poco común","Común"))))) | M22: 35327.5 | N22: 10638.399 | O22: =IF(M22="","",M22*J22) | P22: =IF(N22="","",N22*J22) | Q22: 0.0052 | R22: 54.51723 | S22: EUROSTOXX50, NASDAQ100 | T22: SI | V22: =Umbrales!$B$9*(K22/1000)^Umbrales!$B$10
A23: JNJ | B23: Johnson & Johnson | C23: United States | D23: US | E23: Salud | F23: Drug Manufacturers - General | G23: NYQ | H23: USD | I23: 611897.31 | J23: =INDEX(FX!$B:$B,MATCH(H23,FX!$A:$A,0)) | K23: =I23*J23 | L23: =IF(U23<>"",U23,IF(K23>=Umbrales!$B$2,"Legendaria",IF(K23>=Umbrales!$B$3,"Épica",IF(K23>=Umbrales!$B$4,"Rara",IF(K23>=Umbrales!$B$5,"Poco común","Común"))))) | M23: 97929.003 | N23: 21037.001 | O23: =IF(M23="","",M23*J23) | P23: =IF(N23="","",N23*J23) | Q23: 0.0216 | R23: 28.820658 | S23: DOW30 | T23: SI | V23: =Umbrales!$B$9*(K23/1000)^Umbrales!$B$10
A24: MA | B24: Mastercard Incorporated | C24: United States | D24: US | E24: Finanzas | F24: Credit Services | G24: NYQ | H24: USD | I24: 528444.23 | J24: =INDEX(FX!$B:$B,MATCH(H24,FX!$A:$A,0)) | K24: =I24*J24 | L24: =IF(U24<>"",U24,IF(K24>=Umbrales!$B$2,"Legendaria",IF(K24>=Umbrales!$B$3,"Épica",IF(K24>=Umbrales!$B$4,"Rara",IF(K24>=Umbrales!$B$5,"Poco común","Común"))))) | M24: 35083.002 | N24: 16257 | O24: =IF(M24="","",M24*J24) | P24: =IF(N24="","",N24*J24) | Q24: 0.0058 | R24: 33.18152 | T24: SI | V24: =Umbrales!$B$9*(K24/1000)^Umbrales!$B$10
A25: INTC | B25: Intel Corporation | C25: United States | D25: US | E25: Tecnología | F25: Semiconductors | G25: NMS | H25: USD | I25: 518672.65 | J25: =INDEX(FX!$B:$B,MATCH(H25,FX!$A:$A,0)) | K25: =I25*J25 | L25: =IF(U25<>"",U25,IF(K25>=Umbrales!$B$2,"Legendaria",IF(K25>=Umbrales!$B$3,"Épica",IF(K25>=Umbrales!$B$4,"Rara",IF(K25>=Umbrales!$B$5,"Poco común","Común"))))) | M25: 57031.999 | N25: -11289 | O25: =IF(M25="","",M25*J25) | P25: =IF(N25="","",N25*J25) | Q25: 0 | S25: NASDAQ100 | T25: SI | V25: =Umbrales!$B$9*(K25/1000)^Umbrales!$B$10
A26: ABBV | B26: AbbVie Inc. | C26: United States | D26: US | E26: Salud | F26: Drug Manufacturers - General | G26: NYQ | H26: USD | I26: 500942.44 | J26: =INDEX(FX!$B:$B,MATCH(H26,FX!$A:$A,0)) | K26: =I26*J26 | L26: =IF(U26<>"",U26,IF(K26>=Umbrales!$B$2,"Legendaria",IF(K26>=Umbrales!$B$3,"Épica",IF(K26>=Umbrales!$B$4,"Rara",IF(K26>=Umbrales!$B$5,"Poco común","Común"))))) | M26: 64385.999 | N26: 6270.0001 | O26: =IF(M26="","",M26*J26) | P26: =IF(N26="","",N26*J26) | Q26: 0.0252 | R26: 80.0791 | T26: SI | V26: =Umbrales!$B$9*(K26/1000)^Umbrales!$B$10
A27: PLTR | B27: Palantir Technologies Inc. | C27: United States | D27: US | E27: Tecnología | F27: Software - Infrastructure | G27: NMS | H27: USD | I27: 482942.65 | J27: =INDEX(FX!$B:$B,MATCH(H27,FX!$A:$A,0)) | K27: =I27*J27 | L27: =IF(U27<>"",U27,IF(K27>=Umbrales!$B$2,"Legendaria",IF(K27>=Umbrales!$B$3,"Épica",IF(K27>=Umbrales!$B$4,"Rara",IF(K27>=Umbrales!$B$5,"Poco común","Común"))))) | M27: 6155.9409 | N27: 3016.692 | O27: =IF(M27="","",M27*J27) | P27: =IF(N27="","",N27*J27) | Q27: 0 | R27: 173.25 | S27: NASDAQ100 | T27: SI | V27: =Umbrales!$B$9*(K27/1000)^Umbrales!$B$10
A28: 0700.HK | B28: Tencent Holdings Limited | C28: China | D28: CN | E28: Comunicación | F28: Internet Content & Information | G28: HKG | H28: HKD | I28: 3762314 | J28: =INDEX(FX!$B:$B,MATCH(H28,FX!$A:$A,0)) | K28: =I28*J28 | L28: =IF(U28<>"",U28,IF(K28>=Umbrales!$B$2,"Legendaria",IF(K28>=Umbrales!$B$3,"Épica",IF(K28>=Umbrales!$B$4,"Rara",IF(K28>=Umbrales!$B$5,"Poco común","Común"))))) | M28: 788483.01 | N28: 235508.01 | O28: =IF(M28="","",M28*J28) | P28: =IF(N28="","",N28*J28) | Q28: 0.0125 | R28: 14.706089 | S28: ASIA_TOP | T28: SI | V28: =Umbrales!$B$9*(K28/1000)^Umbrales!$B$10
A29: CSCO | B29: Cisco Systems, Inc. | C29: United States | D29: US | E29: Tecnología | F29: Communication Equipment | G29: NMS | H29: USD | I29: 448035.59 | J29: =INDEX(FX!$B:$B,MATCH(H29,FX!$A:$A,0)) | K29: =I29*J29 | L29: =IF(U29<>"",U29,IF(K29>=Umbrales!$B$2,"Legendaria",IF(K29>=Umbrales!$B$3,"Épica",IF(K29>=Umbrales!$B$4,"Rara",IF(K29>=Umbrales!$B$5,"Poco común","Común"))))) | M29: 63325 | N29: 13267 | O29: =IF(M29="","",M29*J29) | P29: =IF(N29="","",N29*J29) | Q29: 0.0146 | R29: 34.541035 | S29: DOW30, NASDAQ100 | T29: SI | V29: =Umbrales!$B$9*(K29/1000)^Umbrales!$B$10
A30: CVX | B30: Chevron Corporation | C30: United States | D30: US | E30: Energía | F30: Oil & Gas Integrated | G30: NYQ | H30: USD | I30: 435554.39 | J30: =INDEX(FX!$B:$B,MATCH(H30,FX!$A:$A,0)) | K30: =I30*J30 | L30: =IF(U30<>"",U30,IF(K30>=Umbrales!$B$2,"Legendaria",IF(K30>=Umbrales!$B$3,"Épica",IF(K30>=Umbrales!$B$4,"Rara",IF(K30>=Umbrales!$B$5,"Poco común","Común"))))) | M30: 209384 | N30: 20591 | O30: =IF(M30="","",M30*J30) | P30: =IF(N30="","",N30*J30) | Q30: 0.0327 | R30: 21.370546 | S30: DOW30 | T30: SI | V30: =Umbrales!$B$9*(K30/1000)^Umbrales!$B$10
A31: COST | B31: Costco Wholesale Corporation | C31: United States | D31: US | E31: Consumo básico | F31: Discount Stores | G31: NMS | H31: USD | I31: 435153.01 | J31: =INDEX(FX!$B:$B,MATCH(H31,FX!$A:$A,0)) | K31: =I31*J31 | L31: =IF(U31<>"",U31,IF(K31>=Umbrales!$B$2,"Legendaria",IF(K31>=Umbrales!$B$3,"Épica",IF(K31>=Umbrales!$B$4,"Rara",IF(K31>=Umbrales!$B$5,"Poco común","Común"))))) | M31: 303154 | N31: 9226.0004 | O31: =IF(M31="","",M31*J31) | P31: =IF(N31="","",N31*J31) | Q31: 0.0062 | R31: 47.302505 | S31: NASDAQ100 | T31: SI | V31: =Umbrales!$B$9*(K31/1000)^Umbrales!$B$10
A32: ORCL | B32: Oracle Corporation | C32: United States | D32: US | E32: Tecnología | F32: Software - Infrastructure | G32: NYQ | H32: USD | I32: 395762.47 | J32: =INDEX(FX!$B:$B,MATCH(H32,FX!$A:$A,0)) | K32: =I32*J32 | L32: =IF(U32<>"",U32,IF(K32>=Umbrales!$B$2,"Legendaria",IF(K32>=Umbrales!$B$3,"Épica",IF(K32>=Umbrales!$B$4,"Rara",IF(K32>=Umbrales!$B$5,"Poco común","Común"))))) | M32: 71776.002 | N32: 18736.001 | O32: =IF(M32="","",M32*J32) | P32: =IF(N32="","",N32*J32) | Q32: 0.014 | R32: 22.43127 | T32: SI | V32: =Umbrales!$B$9*(K32/1000)^Umbrales!$B$10
A33: KO | B33: The Coca-Cola Company | C33: United States | D33: US | E33: Consumo básico | F33: Beverages - Non-Alcoholic | G33: NYQ | H33: USD | I33: 394887.95 | J33: =INDEX(FX!$B:$B,MATCH(H33,FX!$A:$A,0)) | K33: =I33*J33 | L33: =IF(U33<>"",U33,IF(K33>=Umbrales!$B$2,"Legendaria",IF(K33>=Umbrales!$B$3,"Épica",IF(K33>=Umbrales!$B$4,"Rara",IF(K33>=Umbrales!$B$5,"Poco común","Común"))))) | M33: 50128.998 | N33: 14316 | O33: =IF(M33="","",M33*J33) | P33: =IF(N33="","",N33*J33) | Q33: 0.0235 | R33: 27.561562 | S33: DOW30 | T33: SI | V33: =Umbrales!$B$9*(K33/1000)^Umbrales!$B$10
A34: PG | B34: The Procter & Gamble Company | C34: United States | D34: US | E34: Consumo básico | F34: Household & Personal Products | G34: NYQ | H34: USD | I34: 363843.52 | J34: =INDEX(FX!$B:$B,MATCH(H34,FX!$A:$A,0)) | K34: =I34*J34 | L34: =IF(U34<>"",U34,IF(K34>=Umbrales!$B$2,"Legendaria",IF(K34>=Umbrales!$B$3,"Épica",IF(K34>=Umbrales!$B$4,"Rara",IF(K34>=Umbrales!$B$5,"Poco común","Común"))))) | M34: 87031.996 | N34: 15754 | O34: =IF(M34="","",M34*J34) | P34: =IF(N34="","",N34*J34) | Q34: 0.0284 | R34: 23.121122 | S34: DOW30 | T34: SI | V34: =Umbrales!$B$9*(K34/1000)^Umbrales!$B$10
A35: MRK | B35: Merck & Co., Inc. | C35: United States | D35: US | E35: Salud | F35: Drug Manufacturers - General | G35: NYQ | H35: USD | I35: 363587.08 | J35: =INDEX(FX!$B:$B,MATCH(H35,FX!$A:$A,0)) | K35: =I35*J35 | L35: =IF(U35<>"",U35,IF(K35>=Umbrales!$B$2,"Legendaria",IF(K35>=Umbrales!$B$3,"Épica",IF(K35>=Umbrales!$B$4,"Rara",IF(K35>=Umbrales!$B$5,"Poco común","Común"))))) | M35: 66568.999 | N35: 3172.9999 | O35: =IF(M35="","",M35*J35) | P35: =IF(N35="","",N35*J35) | Q35: 0.0239 | R35: 116.96031 | S35: DOW30 | T35: SI | V35: =Umbrales!$B$9*(K35/1000)^Umbrales!$B$10
A36: BAC | B36: Bank of America Corporation | C36: United States | D36: US | E36: Finanzas | F36: Banks - Diversified | G36: NYQ | H36: USD | I36: 359357.35 | J36: =INDEX(FX!$B:$B,MATCH(H36,FX!$A:$A,0)) | K36: =I36*J36 | L36: =IF(U36<>"",U36,IF(K36>=Umbrales!$B$2,"Legendaria",IF(K36>=Umbrales!$B$3,"Épica",IF(K36>=Umbrales!$B$4,"Rara",IF(K36>=Umbrales!$B$5,"Poco común","Común"))))) | M36: 113931 | N36: 32125 | O36: =IF(M36="","",M36*J36) | P36: =IF(N36="","",N36*J36) | Q36: 0.0237 | R36: 12.473301 | T36: SI | V36: =Umbrales!$B$9*(K36/1000)^Umbrales!$B$10
A37: LRCX | B37: Lam Research Corporation | C37: United States | D37: US | E37: Tecnología | F37: Semiconductor Equipment & Materials | G37: NMS | H37: USD | I37: 359058.7 | J37: =INDEX(FX!$B:$B,MATCH(H37,FX!$A:$A,0)) | K37: =I37*J37 | L37: =IF(U37<>"",U37,IF(K37>=Umbrales!$B$2,"Legendaria",IF(K37>=Umbrales!$B$3,"Épica",IF(K37>=Umbrales!$B$4,"Rara",IF(K37>=Umbrales!$B$5,"Poco común","Común"))))) | M37: 23232.69 | N37: 7265.3962 | O37: =IF(M37="","",M37*J37) | P37: =IF(N37="","",N37*J37) | Q37: 0.0044 | R37: 49.8125 | S37: NASDAQ100 | T37: SI | V37: =Umbrales!$B$9*(K37/1000)^Umbrales!$B$10
A38: UNH | B38: UnitedHealth Group Incorporated | C38: United States | D38: US | E38: Salud | F38: Healthcare Plans | G38: NYQ | H38: USD | I38: 355106.46 | J38: =INDEX(FX!$B:$B,MATCH(H38,FX!$A:$A,0)) | K38: =I38*J38 | L38: =IF(U38<>"",U38,IF(K38>=Umbrales!$B$2,"Legendaria",IF(K38>=Umbrales!$B$3,"Épica",IF(K38>=Umbrales!$B$4,"Rara",IF(K38>=Umbrales!$B$5,"Poco común","Común"))))) | M38: 450059.01 | N38: 15884 | O38: =IF(M38="","",M38*J38) | P38: =IF(N38="","",N38*J38) | Q38: 0.0246 | R38: 24.286064 | S38: DOW30 | T38: SI | V38: =Umbrales!$B$9*(K38/1000)^Umbrales!$B$10
A39: AMAT | B39: Applied Materials, Inc. | C39: United States | D39: US | E39: Tecnología | F39: Semiconductor Equipment & Materials | G39: NMS | H39: USD | I39: 354444.44 | J39: =INDEX(FX!$B:$B,MATCH(H39,FX!$A:$A,0)) | K39: =I39*J39 | L39: =IF(U39<>"",U39,IF(K39>=Umbrales!$B$2,"Legendaria",IF(K39>=Umbrales!$B$3,"Épica",IF(K39>=Umbrales!$B$4,"Rara",IF(K39>=Umbrales!$B$5,"Poco común","Común"))))) | M39: 30837 | N39: 9267.0003 | O39: =IF(M39="","",M39*J39) | P39: =IF(N39="","",N39*J39) | Q39: 0.0046 | R39: 40.056503 | S39: NASDAQ100 | T39: SI | V39: =Umbrales!$B$9*(K39/1000)^Umbrales!$B$10
A40: 1398.HK | B40: Industrial and Commercial Bank of China Limited | C40: China | D40: CN | E40: Finanzas | F40: Banks - Diversified | G40: HKG | H40: HKD | I40: 2742546.3 | J40: =INDEX(FX!$B:$B,MATCH(H40,FX!$A:$A,0)) | K40: =I40*J40 | L40: =IF(U40<>"",U40,IF(K40>=Umbrales!$B$2,"Legendaria",IF(K40>=Umbrales!$B$3,"Épica",IF(K40>=Umbrales!$B$4,"Rara",IF(K40>=Umbrales!$B$5,"Poco común","Común"))))) | M40: 682491.97 | N40: 361632.01 | O40: =IF(M40="","",M40*J40) | P40: =IF(N40="","",N40*J40) | Q40: 0.0491 | R40: 6.809735 | S40: ASIA_TOP | T40: SI | V40: =Umbrales!$B$9*(K40/1000)^Umbrales!$B$10
...

Sheet FX
A1: Moneda | B1: USD por unidad | C1: Fuente
A2: AUD | B2: 0.69309676 | C2: Yahoo Finance AUDUSD=X, cierre 2026-10-15
A3: CHF | B3: 1.2058798 | C3: Yahoo Finance CHFUSD=X, cierre 2026-10-15
A4: CNY | B4: 0.14945896 | C4: Yahoo Finance CNYUSD=X, cierre 2026-10-15
A5: DKK | B5: 0.15008615 | C5: Yahoo Finance DKKUSD=X, cierre 2026-10-15
A6: EUR | B6: 1.1222085 | C6: Yahoo Finance EURUSD=X, cierre 2026-10-15
A7: GBP | B7: 1.3258907 | C7: Yahoo Finance GBPUSD=X, cierre 2026-10-15
A8: HKD | B8: 0.1274361 | C8: Yahoo Finance HKDUSD=X, cierre 2026-10-15
A9: INR | B9: 0.010527978 | C9: Yahoo Finance INRUSD=X, cierre 2026-10-15
A10: JPY | B10: 0.0063383402 | C10: Yahoo Finance JPYUSD=X, cierre 2026-10-15
A11: KRW | B11: 0.0007440974 | C11: Yahoo Finance KRWUSD=X, cierre 2026-10-15
A12: NOK | B12: 0.10504422 | C12: Yahoo Finance NOKUSD=X, cierre 2026-10-15
A13: SAR | B13: 0.2664535 | C13: Yahoo Finance SARUSD=X, cierre 2026-10-15
... A16: USD | B16: 1 | C16: Yahoo Finance USDUSD=X, cierre 2026-10-15

Sheet Umbrales
A1: Rareza | B1: Cap. mínima (M USD) | C1: Probabilidad gacha | D1: Empresas | E1: % del total
A2: Legendaria | B2: 1200000 | C2: 0.01 | D2: =COUNTIFS(Empresas!$L:$L,A2,Empresas!$T:$T,"SI") | E2: =IF(SUM($D$2:$D$6)=0,0,D2/SUM($D$2:$D$6))
A3: Épica | B3: 350000 | C3: 0.05 | D3: =COUNTIFS(Empresas!$L:$L,A3,Empresas!$T:$T,"SI") | E3: =IF(SUM($D$2:$D$6)=0,0,D3/SUM($D$2:$D$6))
A4: Rara | B4: 150000 | C4: 0.12 | D4: =COUNTIFS(Empresas!$L:$L,A4,Empresas!$T:$T,"SI") | E4: =IF(SUM($D$2:$D$6)=0,0,D4/SUM($D$2:$D$6))
A5: Poco común | B5: 55000 | C5: 0.27 | D5: =COUNTIFS(Empresas!$L:$L,A5,Empresas!$T:$T,"SI") | E5: =IF(SUM($D$2:$D$6)=0,0,D5/SUM($D$2:$D$6))
A6: Común | B6: 0 | C6: 0.55 | D6: =COUNTIFS(Empresas!$L:$L,A6,Empresas!$T:$T,"SI") | E6: =IF(SUM($D$2:$D$6)=0,0,D6/SUM($D$2:$D$6))
A7: Total | C7: =SUM(C2:C6) | D7: =SUM(D2:D6)
A9: Coeficiente ingresos | B9: 0.05
A10: Exponente ingresos | B10: 0.75
A11: ingresos/s = coeficiente × (Cap. USD en miles de millones) ^ exponente
